Workbook
Name 隧道止水带现场质量检查记录表: [1]隧道记录表目录!#REF!
Name 隧道止水带现场质量检查记录表: [1]隧道记录表目录!#REF!
Name 隧道止水带现场质量检查记录表: [1]隧道记录表目录!#REF!
Name 隧道止水带现场质量检查记录表: [1]隧道记录表目录!#REF!
Name 隧道止水带现场质量检查记录表: [1]隧道记录表目录!#REF!
Name 隧道止水带现场质量检查记录表: [2]隧道记录表目录!$C$37
Name 隧道止水带现场质量检查记录表: [3]隧道记录表目录!$C$37
Name 隧道止水带现场质量检查记录表: '隧道记录表目录 (改)'!#REF!
Name 隧道止水带现场质量检查记录表: 隧道记录表目录!#REF!
Name 隧道止水带现场质量检查记录表1: [1]隧道记录表目录!#REF!
Name 隧道止水带现场质量检查记录表1: [1]隧道记录表目录!#REF!
Name 隧道止水带现场质量检查记录表1: [1]隧道记录表目录!#REF!
Name 隧道止水带现场质量检查记录表1: [1]隧道记录表目录!#REF!
Name 隧道止水带现场质量检查记录表1: [1]隧道记录表目录!#REF!
Name 隧道止水带现场质量检查记录表1: [2]隧道记录表目录!$C$37
Name 隧道止水带现场质量检查记录表1: [3]隧道记录表目录!$C$37
Name 隧道止水带现场质量检查记录表1: '隧道记录表目录 (改)'!#REF!
Name 隧道止水带现场质量检查记录表1: 隧道记录表目录!#REF!

Sheet 隧道记录表目录 (改)
A1: 隧道工程记录表目录
A2: 序号 | B2: 编号 | C2: 内容 | D2: 备注
A3: 1 | B3: SDJ1 | C3: 隧道总体现场检查记录表 | D3: 与检表一致，拟删除
A4: 2 | B4: SDJ2 | C4: 隧道成洞净空检查记录表
A5: 3 | B5: SDJ3 | C5: 隧道模筑混凝土渗漏水检查记录表
A6: 4 | B6: SDJ4 | C6: 明洞防水层检查记录表
A7: 5 | B7: SDJ5 | C7: 明洞回填检查记录表
A8: 6 | B8: SDJ6 | C8: 隧道洞身开挖检查记录表
A9: 7 | B9: SDJ7 | C9: 隧道仰拱底（隧底）基础检查记录表
A10: 8 | B10: SDJ8 | C10: 隧道开挖地质调查原始记录表
A11: 9 | B11: SDJ9 | C11: 隧道喷射混凝土检查记录表
A12: 10 | B12: SDJ10 | C12: 隧道锚杆检查记录表
A13: 11 | B13: SDJ11 | C13: 隧道钢筋网安装检查记录表
A14: 12 | B14: SDJ12 | C14: 钢拱支撑(格构梁)构件加工检查记录表
A15: 13 | B15: SDJ13 | C15: 隧道钢拱支撑(格栅)安设检查记录表
... A18: 16 | B18: SDJ16 | C18: 隧道全断面衬砌模板台车安装检查记录表
A19: 17 | B19: SDJ17 | C19: 衬砌模板安装检查记录表 | D19: 新增，依据2020隧道施工技术规范表9.10.5模板安装质量控制标准。
A20: 18 | B20: SDJ18 | C20: 隧道混凝土衬砌拆模后检查记录表
A21: 19 | B21: SDJ19 | C21: 隧道预留设备洞、预埋管线、加强构件检查记录表
A22: 20 | B22: SDJ20 | C22: 隧道防水层安装检查记录表
A23: 21 | B23: SDJ21 | C23: 隧道防水板焊缝充气检查记录表 | D23: 新增，依据2017检评标准附录S防水板焊缝施工质量检测方法。
A24: 22 | B24: SDJ22 | C24: 隧道止水带施工检查记录表 | D24: 新增，依据2020隧道施工技术规范表11.4.8止水带安装质量标准。
A25: 23 | B25: SDJ23 | C25: 隧道排水管安设检查记录表
A26: 24 | B26: SDJ24 | C26: 排水沟（管）现场检查记录表 | D26: 新增。依据2020隧道施工技术规范表11.4.3洞内边沟、洞外路堑边沟断面尺寸质量标准。
A27: 25 | B27: SDJ25 | C27: 隧道检修道、电缆沟检查记录表
A28: 26 | B28: SDJ26 | C28: 超前小导管现场质量检查记录表
A29: 27 | B29: SDJ27 | C29: 管棚施工现场质量检查记录表
A30: 28 | B30: SDJ28 | C30: 拱顶下沉量测记录表
A31: 29 | B31: SDJ29 | C31: 周边收敛量测记录表
A32: 30 | B32: SDJ30 | C32: 时间-周边收敛数据分析曲线图
A33: 31 | B33: SDJ31 | C33: 时间-拱顶下沉数据分析曲线图

Sheet 隧道记录表目录
A1: 隧道工程记录表目录
A2: 序号 | B2: 编号 | C2: 内容 | D2: 备注
A3: 1 | B3: SDJ1 | C3: 隧道总体现场检查记录表 | G3: =HYPERLINK("#SDJ1!A2",'SDJ1（拟删）'!A2) -> 隧道总体现场检查记录表
A4: 2 | B4: SDJ2 | C4: 隧道成洞净空检查记录表 | G4: =HYPERLINK("#SDJ2!A2",#REF!) -> #REF!
A5: 3 | B5: SDJ3 | C5: 隧道模筑混凝土渗漏水检查记录表 | G5: =HYPERLINK("#SDJ3!A2",'SDJ3'!A2) -> 隧道模筑混凝土渗漏水检查记录表
A6: 4 | B6: SDJ4 | C6: 明洞防水层检查记录表 | G6: =HYPERLINK("#SDJ4!A2",'SDJ4'!A2) -> 明洞防水层检查记录表
A7: 5 | B7: SDJ5 | C7: 明洞回填检查记录表 | G7: =HYPERLINK("#SDJ5!A2",'SDJ5'!A2) -> 明洞回填检查记录表
A8: 6 | B8: SDJ6 | C8: 隧道洞身开挖检查记录表 | G8: =HYPERLINK("#SDJ6!A2",'SDJ6'!A2) -> 隧道洞身开挖检查记录表
A9: 7 | B9: SDJ7 | C9: 隧道仰拱底（隧底）基础检查记录表 | G9: =HYPERLINK("#SDJ7!A2",'SDJ7'!A2) -> 隧道仰拱底（隧底）检查记录表
A10: 8 | B10: SDJ8 | C10: 隧道开挖地质调查原始记录表 | G10: =HYPERLINK("#SDJ8!A2",'SDJ8'!A2) -> 隧道开挖地质调查原始记录表
A11: 9 | B11: SDJ9 | C11: 隧道喷射混凝土检查记录表 | G11: =HYPERLINK("#SDJ9!A2",'SDJ9'!A2) -> 隧道喷射混凝土检查记录表
A12: 10 | B12: SDJ10 | C12: 隧道锚杆检查记录表 | G12: =HYPERLINK("#SDJ10!A2",'SDJ10'!A2) -> 隧道锚杆检查记录表
A13: 11 | B13: SDJ11 | C13: 隧道钢筋网安装检查记录表 | G13: =HYPERLINK("#SDJ11!A2",'SDJ11'!A2) -> 隧道钢筋网安装检查记录表
A14: 12 | B14: SDJ12 | C14: 钢拱支撑(格构梁)构件加工检查记录表 | G14: =HYPERLINK("#SDJ12!A2",'SDJ12'!A2) -> 钢拱支撑(格构梁)构件加工检查记录表
A15: 13 | B15: SDJ13 | C15: 隧道钢拱支撑(格栅)安设检查记录表 | G15: =HYPERLINK("#SDJ13!A2",'SDJ13'!A2) -> 隧道钢架支护(格栅)安设检查记录表
A16: 14 | B16: SDJ14 | C16: 隧道仰拱、底板、仰拱回填混凝土施工检查记录表 | G16: =HYPERLINK("#SDJ14!A2",'SDJ14'!A2) -> 隧道仰拱、底板、仰拱回填混凝土施工检查记录表
A17: 15 | B17: SDJ15 | C17: 衬砌钢筋安装检查记录表 | G17: =HYPERLINK("#SDJ15!A2",'SDJ15'!A2) -> 衬砌钢筋安装检查记录表
A18: 16 | B18: SDJ16 | C18: 隧道全断面衬砌模板台车安装检查记录表 | G18: =HYPERLINK("#SDJ16!A2",'SDJ16'!A2) -> 隧道全断面衬砌模板台车安装检查记录表
A19: 17 | B19: SDJ17 | C19: 衬砌模板安装检查记录表 | D19: 新增，依据2020隧道施工技术规范表9.10.5模板安装质量控制标准。 | G19: =HYPERLINK("#SDJ17!A2",'SDJ17'!A2) -> 衬砌模板安装检查记录表
A20: 18 | B20: SDJ18 | C20: 隧道混凝土衬砌拆模后检查记录表 | G20: =HYPERLINK("#SDJ18!A2",'SDJ18'!A2) -> 隧道混凝土衬砌拆模后检查记录表
A21: 19 | B21: SDJ19 | C21: 隧道预留设备洞、预埋管线、加强构件检查记录表 | G21: =HYPERLINK("#SDJ19!A2",'SDJ19'!A2) -> 隧道预留设备洞、预埋管线、加强构件检查记录表
A22: 20 | B22: SDJ20 | C22: 隧道防水层安装检查记录表 | G22: =HYPERLINK("#SDJ20!A2",'SDJ20'!A2) -> 隧道防水层安装检查记录表
A23: 21 | B23: SDJ21 | C23: 隧道防水板焊缝充气检查记录表 | D23: 新增，依据2017检评标准附录S防水板焊缝施工质量检测方法。 | G23: =HYPERLINK("#SDJ21!A2",'SDJ21'!A2) -> 隧道防水板焊缝充气检查记录表
A24: 22 | B24: SDJ22 | C24: 隧道止水带施工检查记录表 | D24: 新增，依据2020隧道施工技术规范表11.4.8止水带安装质量标准。 | G24: =HYPERLINK("#SDJ22!A2",'SDJ22'!A2) -> 隧道止水带施工检查记录表
A25: 23 | B25: SDJ23 | C25: 隧道排水管安设检查记录表 | G25: =HYPERLINK("#SDJ23!A2",'SDJ23'!A2) -> 隧道排水管安设检查记录表
A26: 24 | B26: SDJ24 | C26: 排水沟（管）现场检查记录表 | D26: 新增。依据2020隧道施工技术规范表11.4.3洞内边沟、洞外路堑边沟断面尺寸质量标准。 | G26: =HYPERLINK("#SDJ24!A2",'SDJ24'!A2) -> 排水沟（管）现场检查记录表
A27: 25 | B27: SDJ25 | C27: 隧道检修道、电缆沟检查记录表 | G27: =HYPERLINK("#SDJ25!A2",'SDJ25'!A2) -> 隧道检修道、电缆沟检查记录表
A28: 26 | B28: SDJ26 | C28: 超前小导管现场质量检查记录表 | G28: =HYPERLINK("#SDJ26!A2",'SDJ26'!A2) -> 超前小导管现场质量检查记录表
A29: 27 | B29: SDJ27 | C29: 管棚施工现场质量检查记录表 | G29: =HYPERLINK("#SDJ27!A2",'SDJ27'!A2) -> 管棚施工现场质量检查记录表
A30: 28 | B30: SDJ28 | C30: 拱顶下沉量测记录表 | G30: =HYPERLINK("#SDJ28!A2",'SDJ28'!A2) -> 拱顶下沉量测记录表
A31: 29 | B31: SDJ29 | C31: 周边收敛量测记录表 | G31: =HYPERLINK("#SDJ29!A2",'SDJ29'!A2) -> 周边收敛量测记录表
A32: 30 | B32: SDJ30 | C32: 时间-周边收敛数据分析曲线图 | G32: =HYPERLINK("#SDJ30!A2",'SDJ30'!A2) -> 时间-周边收敛数据分析曲线图
A33: 31 | B33: SDJ31 | C33: 时间-拱顶下沉数据分析曲线图 | G33: =HYPERLINK("#SDJ31!A2",'SDJ31'!A2) -> 时间-拱顶下沉数据分析曲线图

Sheet SDJ1（拟删）
A1: 公路工程项目
A2: 隧道总体现场检查记录表
A3: 施工单位： | I3: 标段：
A4: 监理单位： | I4: 标段：
A5: SDJ1
A6: 工程名称 | F6: 施工日期
A7: 桩号及工程部位 | F7: 检查日期
A8: 检 查 项 目 | C8: 规定值或 允许偏差 | D8: 设计值 | E8: 实测值
A9: 车行道宽（mm) | C9: ±10 | M9: 与检表内容一致，拟删除本表
A10: 净总宽（mm) | C10: 不小于设计
A11: 隧道净高（mm) | C11: 不小于设计
A12: 隧道偏位 | C12: 20
A13: 引道中心线与隧道中心线的衔接（mm) | C13: 20
A14: 边仰坡的坡度（mm) | C14: 不大于设计
A15: 检查结果 | D15: □ 自检结果满足规范及设计要求。
A16: 检查人： 检验负责人： 监理员：

Sheet SDJ2
A1: 公路工程项目
A2: 隧道成洞净空检查记录表
A3: 施工单位： | K3: 标段：
A4: 监理单位： | K4: 标段：
A5: SDJ2
A6: 工程名称 | I6: 施工日期
A7: 桩号及工程部位 | I7: 检查日期
A8: 检验部位 | B8: 检查项目 | D8: 规定值或允许偏差 | M8: …
E9: 设计 | F9: 实测 | G9: 设计 | H9: 实测 | I9: 设计 | J9: 实测 | K9: 设计 | L9: 实测 | M9: 设计 | N9: 实测
A10: 0 | B10: 高度 | D10: 不小于设计值
A11: 1-1＇ | B11: 宽度 | D11: 不小于设计值
A12: 1 | B12: 高度 | D12: 不小于设计值
A13: 1＇ | B13: 高度 | D13: 不小于设计值
A14: 2-2＇ | B14: 宽度 | D14: 不小于设计值
A15: 3-3＇ | B15: 宽度 | D15: 不小于设计值
A16: 4-4＇ | B16: 宽度 | D16: 不小于设计值
A17: 5-5＇ | B17: 宽度 | D17: 不小于设计值
A18: 6 | B18: 标高 | D18: /
A19: 备注：表中高度 是以隧道设计线高程 到相应点的相对高。
A20: 检查结果 | D20: □ 自检结果满足规范及设计要求。
A21: 检查人： 质检负责人： 监理员：

Sheet SDJ3
A1: 公路工程项目
A2: 隧道模筑混凝土渗漏水检查记录表
A3: 施工单位： | H3: 标段：
A4: 监理单位： | H4: 标段：
A5: SDJ3
A6: 工程名称 | G6: 施工日期
A7: 桩号及工程部位 | G7: 检查日期
A8: 桩号 | C8: 部位（拱部、边墙、路面） | D8: 渗漏类型
D9: 喷射 | E9: 涌流 | F9: 滴漏 | G9: 浸渗
H17: 渗漏水部位示意图
A18: 渗 漏 整 治 情 况
A19: 渗漏点编号 | B19: 桩 号 | D19: 部 位 | F19: 主要整治方法及日期 | J19: 整治效果
A28: 检查结果 | D28: □ 自检结果满足规范及设计要求。
A29: 检查人： 检验负责人： 监理员：

Sheet SDJ4
A1: 公路工程项目
A2: 明洞防水层检查记录表
A3: 施工单位： | J3: 标段：
A4: 监理单位： | J4: 标段：
A5: SDJ4
A6: 工程名称 | G6: 施工日期
A7: 桩号及工程部位 | G7: 检查日期
A8: 检查项目 | D8: 规定值或 允许偏差 | E8: 设计值 | F8: 实测值
A9: 卷材搭接宽度(mm) | D9: ≥100
A10: 卷材向暗洞延伸长度（mm) | D10: ≥500
A11: 卷材向基底的横向延伸长度(mm) | D11: ≥500
A12: 沥青防水层每层厚度(mm) | D12: ≥2
A13: 缝宽（mm) | C13: 焊接 | D13: ≥10
C14: 粘接 | D14: ≥50
A15: 焊缝密实性（Mpa） | D15: 压力达到0.25MPa时停止充气，保持15min,压力下降在10%内
A16: 拱圈背部检查 | D16: □ 明洞拱墙背面混凝土表面平整圆顺，无钢筋露出及其他尖锐物。
A17: 防水板安装检查 | D17: □ 与拱背密贴、定位稳固，焊接密实，卷材无破损。
A18: 粘土隔水层检查 | D18: □ 在验收后的回填土石上选用粘性好、无杂质石块粘土并夯实。
A19: 检查结果 | D19: □ 自检结果满足规范及设计要求。
A20: 检查人： 检验负责人： 监理员：

Sheet SDJ5
A1: 公路工程项目
A2: 明洞回填检查记录表
A3: 施工单位： | J3: 标段：
A4: 监理单位： | J4: 标段：
A5: SDJ5
A6: 工程名称 | G6: 施工日期
A7: 桩号及工程部位 | G7: 检查日期
A8: 检查项目 | D8: 规定值或 允许偏差 | E8: 设计值
A9: 回填压实 | D9: 符合设计规定
A10: 回填层厚（mm) | D10: ≤300
A11: 两侧回填高差（mm) | D11: ≤500
A12: 回填厚度 | D12: 符合设计规定
A13: 坡度 | D13: 符合设计规定
A14: 回填方式及要求 | C14: 人工回填 | D14: □ 拱圈混凝土强度达到设计强度的75%。
C15: 机械回填 | D15: □ 拱圈混凝土强度达到设计强度。 □ 在拱圈外人工夯填厚度不小于1.0m后进行。
A16: 拱背两侧回填情况 | D16: □ 回填水平宽度小于1.2m范围采用了浆砌片石或同级混凝土回填。 □ 回填料未使用膨胀岩土。 □ 回填对称分层夯实。
A17: 回填过程中外设防水层的损毁及补救情况 | D17: □ 回填过程中，外设防水层无损毁。
A18: 黏土隔水层检查 | D18: □ 黏土隔水层与边坡、仰坡搭接良好。 □ 黏土隔水层封闭紧密。
A19: 检查结果 | D19: □ 自检结果满足规范及设计要求。
A20: 检查人： 检验负责人： 监理员：

Sheet SDJ6
A1: 公路工程项目
A2: 隧道洞身开挖检查记录表
A3: 施工单位： | S3: 标段：
A4: 监理单位： | S4: 标段：
A5: SDJ6
A6: 工程名称 | H6: 围岩级别 | L6: □Ⅰ级 □Ⅱ级 □Ⅲ级 □Ⅳ级 □Ⅴ级 □Ⅵ级
A7: 桩号及部位 | H7: 开挖方法 | L7: □全断面 □台阶 □环形开挖留核心土 □中隔壁 □交叉中隔壁 □双侧壁导坑
A8: 桩号 超+,欠-（mm) 点位 | W8: 取点示意图：
W9: （示意图中用虚线标出起拱线（最大宽度处）位置，起拱线以上为拱部，起拱线以下为边墙。检查点位按规范要求：拱部检查点位从拱顶沿开挖轮廓线每2m布设点位；边墙从起拱线向下每2m布设点位，起拱线处的点位计入边墙检查点位）
W16: 检查结果： □ 自检结果满足规范及设计要求。
A19: 眼迹 保存率 | B19: 本茬炮进尺
B20: 周边眼合计数量
B21: 保留眼迹的周边眼数量
B22: 保存率%
A23: 施工时间
A24: 检查时间
A25: 检查人： 检验负责人： 监理员：

Sheet SDJ7
A1: 公路工程项目
A2: 隧道仰拱底（隧底）检查记录表
A3: 施工单位： | J3: 标段：
A4: 监理单位： | J4: 标段：
A5: SDJ7
A6: 工程名称 | G6: 桩号及工程部位
A7: 取点示意 | C7: 点 位 里 程 | D7: 1 | G7: 0 | J7: 2 | M7: 施工时间 | N7: 检查时间
D8: 高程 | G8: 高程 | J8: 高程
D9: 设计值 （m） | E9: 实测值 （m） | F9: 超-，欠+ （mm） | G9: 设计值 （m） | H9: 实测值 （m） | I9: 超-，欠+ （mm） | J9: 设计值 （m） | K9: 实测值 （m） | L9: 超-，欠+ （mm）
A11: 0:仰拱(隧底)中心 1、2:仰拱拱腰或隧底半宽中点
A15: 仰拱(隧底) 处理情况 | C15: □ 欠挖已凿除。 □ 超挖采用强度不低于C15的混凝土或C20的喷射混凝土回填。
A16: 仰拱(隧底) 清理情况 | C16: □ 无虚渣。 □ 无杂物。 □ 无淤泥。 □ 无积水。
A17: 检查结果 | C17: □ 自检结果满足规范及设计要求。
A18: 检查人： 检验负责人： 监理员：

Sheet SDJ8
A1: 公路工程项目
A2: 隧道开挖地质调查原始记录表
A3: 施工单位： | L3: 标段：
A4: 监理单位： | L4: 标段：
A5: SDJ8
A6: 隧道名称 | H6: 掌子面桩号 | N6: 判定
A7: 岩性指标 | B7: 岩石类型（名称） | N7: □ 坚硬岩 □ 较硬岩 □ 较软岩 □ 软岩 □ 极软岩 □ 土
B8: 岩石强度Rc（MPa） | D8: □（Rc＞60） | F8: □ （60≥Rc＞30） | H8: □ （30≥Rc＞15） | J8: □ （15≥Rc＞5） | L8: □ （Rc≤5）
B9: 掌子面状态 | D9: □ 稳定 | F9: □基本稳定 | H9: □ 随时间松弛、掉块 | J9: □ 自稳困难，需及时支护 | L9: □ 正面不能自稳，需超前支护
A10: 岩体完整状态 | B10: 地质构造影响程度 | F10: □ 轻微 | H10: □ 较重 | J10: □ 严重 | L10: □ 极严重 | N10: □ 完整 □ 较完整 □ 较破碎 □ 破碎 □ 极破碎
B11: 地质结构面 | C11: 间距（m） | D11: □ ＞1.5 | F11: □ 0.6~1.5 | H11: □ 0.2~0.6 | J11: □ 0.06~0.2 | L11: □ ＜0.06
C12: 延伸性 | D12: □ 极差 | F12: □ 差 | H12: □ 中等 | J12: □ 好 | L12: □ 极好
C13: 粗糙度 | D13: □ 明显台阶状 | F13: □ 粗糙 | H13: □ 波纹状 | J13: □ 平整光滑有擦痕 | L13: □ 平整光滑
C14: 张开性（mm） | D14: □ 密闭 ＜0.1 | F14: □ 部分张开 0.1~0.5 | H14: □ 张开 0.5~1.0 | J14: □ 无填充 张开＞1.0 | L14: □ 粘土填充
B15: 风化程度 | D15: □ 未风化 | F15: □ 微风化 | H15: □ 弱风化 | J15: □ 强风化 | L15: □ 全风化
B16: 简要说明
A17: 地下水状态 | D17: 渗水量L/（min·10m） | F17: □ ＜10 干燥或湿润 | H17: □ 10~25 偶有渗水 | L17: □ 25~125 经常渗水 | N17: □ 干燥或湿润 □ 偶有渗水 □ 经常渗水
A18: 初始应力状态 | D18: 埋深H= m的地质构造应力状态 | H18: 其他
A20: 围岩级别 | D20: □ Ⅰ | F20: □ Ⅱ | H20: □ Ⅲ | J20: □ Ⅳ | L20: □ Ⅴ | N20: □ Ⅵ
A21: 工程措施及有关参数
A22: 原设计主要地质情况和处理措施 | I22: 现建议处理措施
A24: 地 质 素 描 | C24: 现象描述 | D24: （偏帮现象、岩爆现象、渗水涌水状态、发生时间等）
C25: 图 示 | D25: 掌子面地质素描（隧道规范附录C) | J25: 侧面地质素描（隧道规范附录C)
C26: 图形描述
A27: 检查人： 检验负责人： 监理员：

Sheet SDJ9
A1: 公路工程项目
A2: 隧道喷射混凝土检查记录表
A3: 施工单位： | J3: 标段：
A4: 监理单位： | J4: 标段：
A5: SDJ9
A6: 工程名称 | H6: 施工日期
A7: 桩号及工程部位 | H7: 检查日期
A8: 衬砌类型 | H8: 喷射混凝土强度等级
A9: 施工配合比 | D9: 水胶比 | F9: 水泥 | G9: 砂 | I9: 石 | J9: 外加 | L9: 钢纤维
A11: 检查项目 | D11: 规定值或 允许偏差 | F11: 设计值 | G11: 实测值
A12: 初喷厚度(mm) | D12: 20~50mm；最小厚度≥20mm
A13: 空洞检测 | D13: 无空洞，无杂物
A14: 支护净空(mm) | D14: 不小于设计值
A15: 喷射混凝土表面平整度 | D15: D/L≤1/6
A16: 成品厚度检查
A17: 检查桩号 | E17: 设计厚度（mm) | I17: 规定值或允许偏差 | J17: 平均厚度≥设计厚度；60%的检查点厚度≥设计厚度；最小厚度≥0.6倍设计厚度，且≥50mm
A18: 左侧点位 | C18: 实测值（mm) | E18: 右侧点位 | G18: 实测值
A19: 0（拱顶）
A20: 1 | E20: 1＇
A21: 2 | E21: 2＇
A22: 3 | E22: 3＇
A23: 4 | E23: 4＇
A24: 5 | E24: 5＇
A25: 6 | E25: 6＇
A26: 7 | E26: 7＇ | I26: 喷射混凝土强度报
A27: 8 | E27: 8＇ | I27: 龄期（天） | J27: 试验报告单编号 | L27: 强度（MPa）
A28: 9 | E28: 9＇ | I28: 28
A29: 喷面外观质量 | D29: □ 喷射混凝土表面无漏喷、无离鼓。 □ 钢筋网和钢架无外露。
A30: 检查结果 | D30: □ 自检结果满足规范及设计要求。
A31: 检查人： 检验负责人： 监理员：

Sheet SDJ10
A1: 公路工程项目
A2: 隧道锚杆检查记录表
A3: 施工单位： | K3: 标段：
A4: 监理单位： | K4: 标段：
A5: SDJ10
A6: 工程名称 | H6: 施工日期
A7: 桩号及工程部位 | H7: 检查日期
A8: 锚杆类型 | H8: 衬砌类型
A9: 检查项目 | C9: 规定值或 允许偏差 | E9: 设计值 | F9: 实测值
A10: 锚杆直径（mm) | C10: 符合设计要求
A11: 锚杆数量（根） | C11: 满足设计要求 | H11: 锚杆孔位(mm)
A12: 锚杆孔位（mm) | B12: 环向间距 | C12: ±150
B13: 纵向排距
A14: 孔径（mm) | C14: ≥锚杆杆体直径+15 | K14: 1、锚杆检查频率：随机抽查不少于锚杆数的10%。 2、检查部位编号 (1)拱顶位置的锚杆编为1。 (2)路线右侧自上而下编号 为2,3,4…… (3)路线左侧自上而下编号为2＇3＇4＇…… 3、钻孔前应按设计布置要求，标出钻孔位置。实际检查： （1）环向偏离：拱顶方向下“+”，反之为“-”。 （2）纵向偏离：撑子面方向为“+”，反之为“-”。
A15: 锚杆长度（mm) | C15: ±100
A16: 钻孔深度（mm) | C16: ±50
A17: 锚头（mm) | C17: 锚杆外露长度≤100
A18: 锚杆锚固密实度 | C18: 满足设计要求：设计未要求时，锚固质量等级不低于B级
A19: 安设 质量 综合 评价 | B19: 锚头 | E19: □ 锚杆垫板与喷射混凝土之间空隙采用M20水泥砂浆填实，与喷射混凝土层密贴，无间隙。 □ 锚杆杆体外露多余长度已截除，外露长度≤100mm。 □锚杆外露头和垫板进行了防锈处理并满足防水板铺设对基面的要求。
B20: 锚杆安设方向 | E20: □ 系统锚杆基本与开挖轮廓线垂直，且垂直偏差小于20°。 □ 局部锚杆与岩层面或主要结构面成大角度相交。
B21: 锚杆杆体 | E21: □ 钢筋无锈蚀、杆体无凹痕、无弯曲。
B22: 锚杆注浆质量 | E22: □ 饱满、密实、无空洞。
A23: 检查结果 | E23: □ 自检结果满足规范及设计要求。
A24: 检查人： 检验负责人： 监理员：

Sheet SDJ11
A1: 公路工程项目
A2: 隧道钢筋网安装检查记录表
A3: 施工单位： | J3: 标段：
A4: 监理单位： | J4: 标段：
A5: SDJ11
A6: 工程名称 | G6: 施工日期
A7: 桩号及工程部位 | G7: 检查日期
A8: 检查项目 | D8: 规定值或 允许偏差 | E8: 设计值 | F8: 实测值
A9: 钢筋直径(mm) | D9: 满足设计要求
A10: 网格尺寸(mm) | D10: ±10
A11: 钢筋网的钢筋数量（根） | C11: 环向 | D11: 满足设计要求
C12: 纵向 | D12: 满足设计要求
A13: 钢筋保护层厚(mm) | D13: ≥20
A14: 铺挂面积（m2） | D14: 满足设计要求
A15: 搭接长度(mm) | D15: ≥30d（d为钢筋直径），且不小于一个网格长边尺寸）
A16: 钢筋网与受喷面的距离(mm) | D16: ≤50
A17: 外观检查 | D17: □ 钢筋无锈蚀。 □ 杆体无凹曲、无弯曲。
A18: 检查结果 | D18: □ 自检结果满足规范及设计要求。
A19: 检查人： 检验负责人： 监理员：

Sheet SDJ12
A1: 公路工程项目
A2: 钢拱支撑(格构梁)构件加工检查记录表
A3: 施工单位： | N3: 标段：
A4: 监理单位： | N4: 标段：
A5: SDJ12
A6: 工程名称 | J6: 施工日期
A7: 桩号及工程部位 | J7: 检查日期
A8: 检查构件 名称、规格 | J8: 衬砌类型
A9: 几何尺寸检查 | B9: 构件编号 | C9: A 单元 | G9: B单元 | K9: C单元 | O9: D单元
B10: 检查项目 | C10: 数量 （节） | D10: 节长（mm） | E10: 半径(mm) | F10: 角度 (°) | G10: 数量 （节） | H10: 节长（mm） | I10: 半径(mm) | J10: 角度 (°) | K10: 数量 （节） | L10: 节长（mm） | M10: 半径(mm) | N10: 角度 (°) | O10: 数量 （节） | P10: 节长（mm） | Q10: 半径(mm) | R10: 角度 (°)
B11: 设计值
B12: 实测值
B13: 构件编号 | C13: E单元 | G13: F单元 | K13: G单元 | O13: H单元
B14: 检查项目 | C14: 数量 （节） | D14: 节长（mm） | E14: 半径(mm) | F14: 角度 (°) | G14: 数量 （节） | H14: 节长（mm） | I14: 半径(mm) | J14: 角度 (°) | K14: 数量 （节） | L14: 节长（mm） | M14: 半径(mm) | N14: 角度 (°) | O14: 数量 （节） | P14: 节长（mm） | Q14: 半径(mm) | R14: 角度 (°)
B15: 设计值
B16: 实测值
A17: 连接钢板加工及端部焊接情况 | E17: □ 钢架节段两端采用焊接连接钢板。 □ 连接钢板尺寸满足设计要求。 □ 连接钢板上螺栓孔大于4个，采用冲压或铣切成孔，无毛刺。
A18: 分段拼装成刚拱支撑后的总体比样误差
A19: 钢架拼装点位检查示意图 | J19: 拱顶对齐，拱顶、两拱腰及拱脚误差
J21: 点位 | N21: 3 | O21: 1 | P21: 0 | Q21: 2 | R21: 4
J22: 周边偏差(mm)
J23: 平面翘曲（mm)
A24: 综合质量评价 | D24: □ 钢架加工的几何尺寸、试拼装形状符合规范及设计要求。
A25: 检查结果 | D25: □ 自检结果满足规范及设计要求。
A26: 检查人： 检验负责人： 监理员：

Sheet SDJ13
A1: 公路工程项目
A2: 隧道钢架支护(格栅)安设检查记录表
A3: 施工单位： . | J3: 标段： 1
A4: 监理单位： . | J4: 标段： 1
A5: SDJ13
A6: 工程名称 | K6: 桩号及工程部位
A7: 围岩衬砌类型 | H7: 规格型号 | P7: 设置间距（mm)
A8: 里程 | C8: 钢支撑拱顶 | F8: 横向安装偏差 | K8: 连接钢筋 | M8: 与钢架焊接的定位锚杆数量（根) | N8: 格栅钢筋直径(mm) | O8: 连接钢板螺栓个数(个) | P8: 格栅钢筋与钢板焊接 | R8: 锁脚锚杆（管） | V8: 施工及检查日期
C9: 设计标高(m) | D9: 实测标高(m) | E9: 偏差(mm) | F9: 设计半宽 (mm) | G9: 实测宽度（mm） | K9: 数量（根） | L9: 间距（mm) | R9: 长度 （mm) | S9: 数量 (根） | T9: 孔径 | U9: 钻孔 角度（°）
G10: 左侧 | H10: 偏差 | I10: 右侧 | J10: 偏差
A26: 本段合计：钢支撑（格构梁） 榀 ，锚脚锚杆（管） 根，钢架连接钢筋 根。
A27: 本段设置综合评价 | E27: □ 连接钢板与钢架焊接牢固，无假焊、漏焊。 □ 钢架紧靠初喷面，基底无虚渣及杂物。 □ 锁脚锚杆（管）安装位置、与钢架连接、焊接符合设计及规范要求。 □ 锁脚锚杆（管）牢固，焊接符合设计及规范要求。 □ 锁脚锚杆（管）锚孔及管内注浆密实饱满。
A28: 外观检查 | E28: □ 连接钢板平面无翘曲。
A29: 检查结果 | E29: □ 自检结果满足规范及设计要求。
A30: 检查人： 检验负责人： 监理员：

Sheet SDJ14
A1: 公路工程项目
A2: 隧道仰拱、底板、仰拱回填混凝土施工检查记录表
A3: 施工单位： | J3: 标段：
A4: 监理单位： | J4: 标段：
A5: SDJ14
A6: 工程名称 | G6: 施工日期
A7: 桩号及工程部位 | G7: 检查日期
A8: 检查项目 | C8: 规定值或 允许偏差 | D8: 设计值 | E8: 实测值(m)
A9: 仰拱（底板）厚度
A10: 坍落度（mm) | B10: <100 | C10: ±20
B11: ≥100 | C11: ±30
A12: 仰拱底面高程、底板或仰拱回填顶面（底板）高程检查
A13: 取点示意 | C13: 里程 点位
A14: 0：仰拱（隧底）或回填底面之中心 1、2:仰拱（隧底）或回填半宽中点 3、4:仰拱（隧底）或回填左右边。 | D14: 设计值 (m) | E14: 实测值 (m) | F14: 偏差 (mm) | G14: 设计值 (m) | H14: 实测值 (m) | I14: 偏差 (mm) | J14: 设计值 (m) | K14: 实测值 (m) | L14: 偏差 (mm)
C15: 0
C16: 1
C17: 2
C18: 3
C19: 4
A20: 误差的对标检查处理 | D20: □ 仰拱的曲率、高程符合设计要求，对标检查在允许误差之内。
A21: 混凝土表面 | D21: □ 拆模后的混凝土结构表面密实平整、颜色均匀。 □ 混凝土表面无露筋、孔洞、疏松、无麻面、缺棱掉角等缺陷。 □ 混凝土表面无深度大于5mm,长度大于10mm的蜂窝。
A22: 检查结果 | D22: □ 自检结果满足规范及设计要求。
A23: 检查人： 检验负责人： 监理员：

Sheet SDJ15
A1: 公路工程项目
A2: 衬砌钢筋安装检查记录表
A3: 施工单位： | K3: 标段：
A4: 监理单位： | K4: 标段：
A5: SDJ15
A6: 工程名称 | H6: 施工日期
A7: 桩号及工程部位 | H7: 检查日期
A8: 检 查 项 目 | D8: 规定值或 允许偏差 | E8: 设计值 | F8: 实测值
A9: 钢筋直径(mm) | D9: 符合设计
A10: 主筋钢筋长度 | D10: 符合设计
A11: 主筋纵向间距（mm) | D11: ±10
A12: 纵筋间距（mm) | D12: 符合设计
A13: 主筋数量(根) | D13: 符合设计
A14: 两层主筋间距（mm) | D14: ±5
A15: 箍筋间距(mm) | D15: ±20
A16: 箍筋数量(根) | D16: 符合设计
A17: 限（定）位钢筋间距(mm) | D17: ±100
A18: 限（定）位钢筋数量（根） | D18: 符合设计
A19: 钢筋搭接长度 | C19: 绑扎 | D19: 满足设计规范
C20: 焊接 | D20: 满足设计规范
C21: 机械连接 | D21: 满足设计规范
A22: 钢筋保护层厚度(mm) | B22: 混凝土垫块厚度 | D22: 不小于设计值
B23: 钢筋与模板间隙、钢筋与防水层间隙 | D23: 不小于设计值
B24: 保护层厚度 | D24: +10，-5
A25: 钢筋焊接、连接 | D25: 符合规范 | F25: □ 钢筋焊接、连接符合相关规范。
A26: 预埋件焊接位置 | D26: 符合设计 | F26: □ 预埋件焊接位置符合设计要求。
A27: 钢筋骨架在模板内固定情况 | D27: 符合设计 | F27: □ 钢筋骨架安装采取了定位措施。 □ 钢筋骨架与模板、防水层的间隙安装了满足设计要求的混凝土垫块。
A28: 外观检查 | D28: □ 钢筋表面无颗粒状或片状老锈及焊渣、烧伤。 □ 钢筋绑扎或焊接的钢筋网和钢架和钢筋骨架无松脱和开焊。 □ 焊接接头、连接套筒无裂纹。
A29: 检查结果 | D29: □ 自检结果满足规范及设计要求。
A30: 检查人： 检验负责人： 监理员：

Sheet SDJ16
A1: 公路工程项目
A2: 隧道全断面衬砌模板台车安装检查记录表
A3: 施工单位： | K3: 标段：
A4: 监理单位： | K4: 标段：
A5: SDJ16
A6: 工程名称 | H6: 施工日期
A7: 桩号及工程部位 | H7: 检查日期
A8: 拱顶高程（0点） | D8: 设计标高A/B（m) | H8: 实测标高A/B（m) | K8: 偏差A/B（mm)
A10: 净空检查 | G10: 点位 | H10: 设计净空(mm) | J10: 实测宽度(mm) | L10: 偏差(mm)
H11: h | I11: b | J11: A | K11: B | L11: A | N11: B
G12: b1
G13: b2
G14: b3
G15: b4
G16: b5
G17: b6
G18: b7
G19: b8
A20: 衬砌厚度检查 | G20: 检查部位 | H20: A | K20: B
H21: 设计厚度(cm) | I21: 实测厚度（cm) | J21: 偏差 (mm) | K21: 设计厚度(cm) | L21: 实测厚度（cm) | N21: 偏差 (mm)
G22: 0
G23: 1
G24: 1’
G25: 2
G26: 2’
G27: 3
G28: 3’
G29: 4
G30: 4’
G31: 5
G32: 5’
G33: 6
G34: 6’
G35: 7
G36: 7’
G37: 振捣窗
A38: 超挖回填要求 | E38: □ 超挖部分采用同级混凝土回填密实。
A39: 模板（板缝、平整、脱模剂、固定情况） | E39: □ 表面光滑、接缝严密，无缝隙，模板安装牢固。
A40: 堵头板安设与固定 | E40: □ 堵头板安装固定牢固，封堵严密。
A41: 伸缩缝、沉降缝、工作缝处置及橡胶止水带安设 | E41: □ 衬砌的施工缝与设计的沉降缝、伸缩缝设在同一位置，且与仰拱混凝土衬砌变形缝竖向对齐。 □ 止水带安设位置及型号规格符合设计要求。 □ 止水带无松脱、扭曲。
...

Sheet SDJ17
A1: 公路工程项目
A2: 衬砌模板安装检查记录表
A3: 施工单位： | F3: 标段：
A4: 监理单位： | F4: 标段： 1
A5: SDJ17
A6: 工程名称 | F6: 施工日期
A7: 桩号或部位 | F7: 检查日期
A8: 检查项目 | C8: 规定值或 允许偏差 | D8: 设计值 | E8: 实测值
A9: 平面位置及高程（mm) | B9: 平面位置 | C9: ±15
B10: 高程 | C10: ±15
A11: 拱顶高程（mm) | C11: +10,0
A12: 起拱线高程（mm) | C12: ±10
A13: 模板平整度（mm） | C13: 5
A14: 预留孔洞、预埋件设置 | D14: □ 孔洞、预埋件预留位置及尺寸符合设计要求。
A15: 安装质量 | D15: □ 模板光滑、未变形，接缝平整不漏浆。 □ 模板拱架形状与衬砌断面形状一致，未侵入衬砌内轮廓。 □ 挡头模板安装牢固、封堵严密。
A16: 检查结果 | D16: □ 自检结果满足规范及设计要求。
A17: 检查人： 检验负责人： 监理员：

Sheet SDJ18
A1: 公路工程项目
A2: 隧道混凝土衬砌拆模后检查记录表
A3: 施工单位： | F3: 标段：
A4: 监理单位： | F4: 标段： 1
A5: SDJ18
A6: 工程名称 | F6: 施工日期
A7: 桩号或部位 | F7: 检查日期
A8: 检查项目 | C8: 规定值或 允许偏差 | D8: 设计值 | E8: 实测值
A9: 衬砌厚度（mm） | C9: 90%的检查点厚度≥大于设计厚度，最小厚度≥0.5倍设计厚度
A10: 中线偏差（mm) | C10: ≤20
A11: 隧道净高（mm） | C11: 不小于设计
A12: 总宽度(mm) | B12: 最大跨度位置 | C12: 不小于设计
B13: 拱脚 | C13: 不小于设计
A14: 管沟顶面处净宽(mm) | B14: 左侧 | C14: 不小于设计
B15: 右侧 | C15: 不小于设计
A16: 蜂窝麻面 | B16: 面积(㎡) | C16: ≤0.5
B17: 深度(mm) | C17: ≤10
A18: 坍落度（mm) | B18: <100 | C18: ±20
B19: ≥100 | C19: ±30
A20: 施工缝表面错台(mm) | C20: ≤20
A21: 墙面平整度 | C21: ≤5
A22: 衬砌衬砌背后密实情况 | D22: □ 衬砌背后无杂物、无空洞。
A23: 检查结果 | D23: □ 自检结果满足规范及设计要求。
A24: 检查人： 检验负责人： 监理员：

Sheet SDJ19
A1: 公路工程项目
A2: 隧道预留设备洞、预埋管线、加强构件检查记录表
A3: 施工单位： | H3: 标段：
A4: 监理单位： | H4: 标段：
A5: SDJ19
A6: 工程名称 | G6: 施工日期
A7: 桩号及工程部位 | G7: 检查日期
A8: 检查项目 | D8: 设置里程及位置 | F8: 规格尺寸检查结果
F9: 预留设备洞 | H9: 预埋管线 | J9: 加强构件
G11: 孔：
G12: 管：
G13: 槽：
G15: 孔：
G17: 孔：
G19: 管：
G20: 槽：
G21: 孔：
G22: 管：
G24: 孔：
A25: 外观检查 | D25: □ 预埋钢板平行度小于等于1%。 □ 预埋钢板位置偏差小于等于于10mm。 □ 预埋件各部分之间及其与混凝土钢筋之间的连接牢固。
A26: 检查结果 | D26: □ 自检结果满足规范及设计要求。
A27: 检查人： 检验负责人： 监理员：

Sheet SDJ20
A1: 公路工程项目
A2: 隧道防水层安装检查记录表
A3: 施工单位： | I3: 标段：
A4: 监理单位： | I4: 标段：
A5: SDJ20
A6: 工程名称 | F6: 施工日期
A7: 桩号及工程部位 | F7: 检查日期
A8: 检 查 项 目 | C8: 规定值或 允许偏差 | D8: 设计值 | E8: 实测值
A9: 搭接长度(mm) | C9: ≥100
A10: 缝宽（mm) | B10: 焊接 | C10: 焊缝宽≥10
B11: 粘接 | C11: 粘缝宽≥50
A12: 固定点间距(m) | B12: 拱部 | C12: 按设计或0.5~0.7m
B13: 侧墙 | C13: 按设计或0.7~1.0m
A14: 焊缝充气检查 | C14: 压力达到0.25MP时停止充气，保持15min,压力下降在10%内
A15: 基面检查 | C15: □ 初期支护表面无钢筋和锚杆头外露、尖硬物凸出、错台或急速凹凸现象。 □ 基面平整度满足D/L≦1/6。
A16: 铺挂检查 | C16: □ 防水层环向整幅铺设，拱部和边墙无纵向搭接。 □ 无纺布采用射钉加热熔垫固定，防水板采用无钉铺挂。 □ 防水板铺挂松弛度适当，任一点能接触岩面。
A17: 土工布材质、规格及安设检查 | C17: 材质 | D17: □ 满足设计要求。
C18: 规格 | D18: □ 满足设计要求。
C19: 安设检查 | D19: □ 无纺布与喷射混凝土表面密贴。 □ 无纺布铺设平顺、无隆起、无褶皱，搭接宽度大于10cm。
A20: 防水板材质、规格及安设检查 | C20: 材质 | D20: □ 满足设计要求。
C21: 规格 | D21: □ 满足设计要求。
C22: 安设检查 | D22: □ 防水板安设表面平顺，连接紧密，无折皱、无气泡、无破损等现象。 □ 防水板接缝、补眼粘贴密实饱满，无气泡、空隙。
A23: 安设质量综合评价 | D23: □ 防水层连接牢固，无破损，满足防水要求。
A24: 检查结果 | D24: □ 自检结果满足规范及设计要求。
A25: 检查人： 检验负责人： 监理员：

Sheet SDJ21
A1: 公路工程项目
A2: 隧道防水板焊缝充气检查记录表
A3: 施工单位： | H3: 标段：
A4: 监理单位： | H4: 标段：
A5: SDJ21
A6: 工程名称 | G6: 施工日期
A7: 桩号及工程部位 | G7: 检查日期
A8: 防水板型号 | G8: 焊接方式
A9: 结构部位及里程 | D9: 充气压力 （MPa） | F9: 保持15min后压力值（MPa） | H9: 保持15min后压力值下降（%） | J9: 检查结果
D10: 要求 | E10: 实测 | F10: 要求 | G10: 实测 | H10: 要求 | I10: 实测
D11: 0.25 | F11: ≥0.225 | H11: ≤10
A20: 外观检查 | D20: □ 肉眼观察，两层焊接在一起的防水板呈透明状、无气泡。
A21: 检查结果 | D21: □ 自检结果满足规范及设计要求。
A22: 检查人： 检验负责人： 监理员：

Sheet SDJ22
A1: 公路工程项目
A2: 隧道止水带施工检查记录表
A3: 施工单位： | J3: 标段：
A4: 监理单位： | J4: 标段：
A5: SDJ22
A6: 工程名称 | H6: 施工日期
A7: 桩号及工程部位 | H7: 检查日期
A8: 检查项目 | D8: 规定值或 允许偏差 | E8: 设计值 | F8: 实测值
A9: 纵向偏离（mm） | D9: ±50
A10: 偏离衬砌中线(mm) | D10: ≤30
A11: 固定点间距(mm) | D11: ±50
A12: 止水带安设质量检查
A13: 检查项目 止水带名称 | D13: 桩号 | G13: 位置 | J13: 规格
A22: 外观检查 | C22: 中埋式 | D22: □ 止水带埋设在衬砌结构设计厚度中央。 □ 止水带平面与衬砌表面平行、与衬砌端头模板正交。 □ 止水带中间空心圆环顺施工缝、变形缝方向并与缝重合。
C23: 背贴式 | D23: □ 止水带沿施工缝位置铺设，止水带中线与缝施工缝重合。 □ 止水带两边与防水板焊接，位置偏差小于10mm。
A24: 检查结果 | D24: □ 自检结果满足规范及设计要求。
A25: 检查人： 检验负责人： 监理员：

Sheet SDJ23
A1: 公路工程项目
A2: 隧道排水管安设检查记录表
A3: 施工单位： | K3: 标段：
A4: 监理单位： | K4: 标段：
A5: SDJ23
A6: 工程名称 | I6: 施工日期
A7: 桩号及工程部位 | I7: 检查日期
A8: 检查范围：K + ～K + 左（右）侧（中心）排水管
A9: 排水管管底高程（接口）检查
A10: 点位桩号 项 目
D11: 左 | E11: 右 | F11: 左 | G11: 右 | H11: 左 | I11: 右 | J11: 左 | K11: 右 | L11: 左 | M11: 右
A12: 标高 | B12: 设计(m）
B13: 实测(m）
B14: 误差(mm)
A15: 排水管安设情况检查
A16: 序号 | B16: 桩号（安装位置） | E16: 排水管名称 | H16: 材质 | J16: 型号 | L16: 规格
A22: 接头连接及安设 | E22: □ 纵向排水管与横向、环向排水管采用T连接。 □ 接头连接牢固，无漏水。
A23: 过滤层设置（管基及干砌片石设置） | E23: □ 设置符合设计要求。
A24: 安设质量综合评价 | E24: □ 环、纵、横排水管安设符合设计及规范要求。 □ 纵向排水管未侵占衬砌结构空间。
A25: 检查结果 | E25: □ 自检结果满足规范及设计要求。
A26: 检查人： 检验负责人： 监理员：

Sheet SDJ24
A1: 公路工程项目
A2: 排水沟（管）现场检查记录表
A3: 施工单位： | I3: 标段：
A4: 监理单位： | I4: 标段：
A5: SDJ24
A6: 工程名称 | F6: 施工日期
A7: 桩号及工程部位 | F7: 检查日期
A8: 检 查 项 目 | C8: 规定值或 允许偏差 | D8: 设计值 | E8: 实测值
A9: 轴线偏位(mm) | C9: 15
A10: 断面净空尺寸或管径(mm) | C10: ±10
A11: 沟壁厚度(mm) | C11: 不小于设计值
A12: 沟底厚度(mm) | C12: 不小于设计值
A13: 沟底高程（mm） | C13: ±20
A14: 沟顶高程（mm） | C14: 0，10
A15: 基底高程（mm) | C15: 符合设计
A16: 排水沟纵坡（%） | C16: 满足设计要求
A17: 检查结果 | D17: □ 自检结果满足规范及设计要求。
A18: 检查人： 检验负责人： 监理员：

Sheet SDJ25
A1: 公路工程项目
A2: 隧道检修道、电缆沟检查记录表
A3: 施工单位： | K3: 标段：
A4: 监理单位： | K4: 标段：
A5: SDJ25
A6: 工程名称 | I6: 施工日期
A7: 桩号及工程部位 | I7: 检查日期
A8: 纵向高程
A9: 检查项目 桩号 左右侧 | C9: 沟底 | I9: 沟顶
C10: 设计（m) | E10: 实测(m) | G10: 高差（mm) | I10: 设计（m) | K10: 实测(m) | M10: 高差（mm)
A15: 水平宽度
A16: 检查项目 桩号 左右侧 | C16: 中线至沟外缘宽度(mm) | I16: 检修道宽度(mm)
C17: 设计 | E17: 实测 | G17: 宽窄 | I17: 设计 | K17: 实测 | M17: 宽窄
A22: 钢筋混凝土盖板制作 及安装检查 | D22: □ 盖板平顺、整齐、无翘曲。 □ 盖板铺设平稳，两端与沟壁的缝隙用砂浆填平，无晃动或吊空。 □ 盖板规格统一，可以互换。
A23: 沟身混凝土质量 | D23: □ 槽壁与边墙连接牢固。
A24: 预埋件及预留孔洞 | D24: □ 槽壁中预埋的管、件预埋牢固，预留孔洞符合设计规定。 □ 槽壁中预埋接地引线与接地预埋件连接牢固、符合设计规定。
A25: 检查结果 | D25: □ 自检结果满足规范及设计要求。
A26: 检查人： 检验负责人： 监理员：

Sheet SDJ26
A1: 公路工程项目
A2: 超前小导管现场质量检查记录表
A3: 施工单位： | H3: 标段：
A4: 监理单位： | H4: 标段：
A5: SDJ26
A6: 工程名称 | G6: 施工日期
A7: 桩号及工程部位 | G7: 检查日期
A8: 浆液配比 | D8: 水泥品种 | E8: 水泥标号 | F8: 水灰 （胶）比 | H8: 水泥 （Kg) | I8: 水 （Kg） | J8: 外加剂 （Kg)
A10: 检查项目 | D10: 规定值或 允许偏差 | E10: 设计值
A11: 管径 | D11: 满足设计要求
A12: 壁厚 | D12: 满足设计要求
A13: 小导管长度（mm) | D13: 不小于设计值
A14: 孔位(mm) | D14: ±50
A15: 外插角（º） | D15: 满足设计要求
A16: 孔深 | D16: 大于钢管长度设计值
A17: 注浆终压（MPa） | D17: 满足设计要求
A18: 注浆总量(m3) | D18: 满足设计要求
A19: 纵向搭接情况 | D19: □ 两组小导管之间纵向水平搭接长度不小于1m。
A20: 检查结果 | D20: □ 自检结果满足规范及设计要求。
A21: 检查人： 检验负责人： 监理员：

Sheet SDJ27
A1: 公路工程项目
A2: 管棚施工现场质量检查记录表
A3: 施工单位： | I3: 标段：
A4: 监理单位： | I4: 标段：
A5: SDJ27
A6: 工程名称 | F6: 施工日期
A7: 桩号及工程部位 | F7: 检查日期
A8: 浆液配合比 | C8: 水泥品种 | D8: 水泥标号 | E8: 水灰（胶）比 | G8: 水泥 （Kg) | H8: 水 （Kg) | I8: 细集料 （Kg) | K8: 外加剂 （Kg)
A10: 检 查 项 目 | C10: 规定值或 允许偏差 | D10: 设计值 | E10: 实测值
A11: 管棚长度(mm) | C11: 不小于设计值
A12: 管棚钢管环向间距(mm) | C12: ±50
A13: 管棚钢管直径(mm) | C13: 符合设计
A14: 壁厚(mm) | C14: 符合设计
A15: 管棚外插角(°) | C15: 符合设计
A16: 钻孔深度(mm) | C16: 大于钢管长度设计值
A17: 成孔直径(mm) | C17: 符合设计
A18: 钢管管内砂浆 | C18: 密实、饱满
A19: 套拱中心位置(mm) | C19: ±50
A20: 套拱拱顶高程(mm) | C20: ±50
A21: 套拱厚度(mm) | C21: ±50
A22: 套拱跨度(mm) | C22: ±100
... A25: 注浆量(m3) | C25: 满足设计
A26: 检查结果 | D26: □ 自检结果满足规范及设计要求。
A27: 检查人： 检验负责人： 监理员：

Sheet SDJ28
A1: 公路工程项目
A2: 拱顶下沉量测记录表
A3: 施工单位： | R3: 标段： 1
A4: 监理单位： | R4: 标段： 1
A5: SJD28
A6: 工程名称 | N6: 施工时间
A7: 桩号或部位 | N7: 检查时间
A8: 测线编号 | B8: 测量时间 | F8: 观测值 | N8: 温度修正值(mm) | O8: 修正后 测点高程 (m) | Q8: 相对初次沉值△u (mm) | R8: 相对上次下沉值 (mm) | S8: 时间 间隔 (d) | T8: 下沉 速率(mm/d) | U8: 备注
B9: 年 | C9: 月 | D9: 日 | E9: 时 | F9: 实测温度°C | G9: 测点高程（m）
G10: 第一次 | I10: 第二次 | K10: 第三次 | M10: 平均值
A19: 检查结果
A21: 检查人： 检验负责人： 监理员：

Sheet SDJ29
A1: 公路工程项目
A2: 周边收敛量测记录表
A3: 施工单位： . | R3: 标段： 1
A4: 监理单位： . | R4: 标段： 1
A5: SJD29
A6: 工程名称 | O6: 施工时间
A7: 桩号或部位 | O7: 检查时间
A8: 测线编号 | B8: 测量时间(dt) | F8: 观测值（mm) | O8: 温度修正值 （mm) | P8: 修正后观测值 （mm) | R8: 相对初次收敛值△u（mm) | S8: 相对上次收敛值 （mm) | T8: 时间 间隔 (d) | U8: 收敛 速率 (mm/d) | V8: 备注
B9: 年 | C9: 月 | D9: 日 | E9: 时 | F9: 温度(°C) | G9: 第一次 | I9: 第二次 | K9: 第三次 | M9: 平均值
A20: 检查结果
A22: 检查人： 检验负责人： 监理员：

Sheet SDJ30
A1: 公路工程项目
A2: 时间-周边收敛数据分析曲线图
A3: 施工单位： . | N3: 标段： 1
A4: 监理单位： . | N4: 标段： 1
A5: SJD30
A6: 工程名称 | J6: 施工时间
A7: 桩号（量测断面） | J7: 检查时间
A8: 量测时间 收敛值 测线编号
A14: 检查结果
I19: 实测收敛值曲线图和收敛函数回归曲线图
A21: 检查人： 检验负责人： 监理员：

Sheet SDJ31
A1: 公路工程项目
A2: 时间-拱顶下沉数据分析曲线图
A3: 施工单位： . | N3: 标段： 1
A4: 监理单位： . | N4: 标段： 1
A5: SJD31
A6: 工程名称 | J6: 施工时间
A7: 桩号（量测断面） | J7: 检查时间
A8: 量测时间 下沉值 测线编号
A14: 检查结果
I19: 实测收敛值曲线图和收敛函数回归曲线图
A21: 检查人： 检验负责人： 监理员：
